[2024-10-08 16:51:04,665] {taskinstance.py:1159} INFO - Dependencies all met for <TaskInstance: get_stocks_dag.AAPL scheduled__2022-01-01T00:00:00+00:00 [queued]>
[2024-10-08 16:51:04,688] {taskinstance.py:1159} INFO - Dependencies all met for <TaskInstance: get_stocks_dag.AAPL scheduled__2022-01-01T00:00:00+00:00 [queued]>
[2024-10-08 16:51:04,688] {taskinstance.py:1356} INFO - 
--------------------------------------------------------------------------------
[2024-10-08 16:51:04,689] {taskinstance.py:1357} INFO - Starting attempt 1 of 1
[2024-10-08 16:51:04,689] {taskinstance.py:1358} INFO - 
--------------------------------------------------------------------------------
[2024-10-08 16:51:04,815] {taskinstance.py:1377} INFO - Executing <Task(_PythonDecoratedOperator): AAPL> on 2022-01-01 00:00:00+00:00
[2024-10-08 16:51:04,825] {standard_task_runner.py:52} INFO - Started process 20064 to run task
[2024-10-08 16:51:04,829] {standard_task_runner.py:79} INFO - Running: ['airflow', 'tasks', 'run', 'get_stocks_dag', 'AAPL', 'scheduled__2022-01-01T00:00:00+00:00', '--job-id', '15', '--raw', '--subdir', 'DAGS_FOLDER/getdag.py', '--cfg-path', '/tmp/tmpiurum9p3', '--error-file', '/tmp/tmp7zm15u29']
[2024-10-08 16:51:04,830] {standard_task_runner.py:80} INFO - Job 15: Subtask AAPL
[2024-10-08 16:51:05,157] {task_command.py:370} INFO - Running <TaskInstance: get_stocks_dag.AAPL scheduled__2022-01-01T00:00:00+00:00 [running]> on host ken
[2024-10-08 16:51:05,531] {taskinstance.py:1569} INFO - Exporting the following env vars:
AIRFLOW_CTX_DAG_OWNER=airflow
AIRFLOW_CTX_DAG_ID=get_stocks_dag
AIRFLOW_CTX_TASK_ID=AAPL
AIRFLOW_CTX_EXECUTION_DATE=2022-01-01T00:00:00+00:00
AIRFLOW_CTX_TRY_NUMBER=1
AIRFLOW_CTX_DAG_RUN_ID=scheduled__2022-01-01T00:00:00+00:00
[2024-10-08 16:51:05,534] {taskinstance.py:1889} ERROR - Task failed with exception
Traceback (most recent call last):
  File "/usr/lib/python3.9/pathlib.py", line 1323, in mkdir
    self._accessor.mkdir(self, mode)
FileNotFoundError: [Errno 2] No such file or directory: '/home/millenagena/Documentos/airflowalura/stocks/AAPL'

During handling of the above exception, another exception occurred:

Traceback (most recent call last):
  File "/usr/lib/python3.9/pathlib.py", line 1323, in mkdir
    self._accessor.mkdir(self, mode)
FileNotFoundError: [Errno 2] No such file or directory: '/home/millenagena/Documentos/airflowalura/stocks'

During handling of the above exception, another exception occurred:

Traceback (most recent call last):
  File "/usr/lib/python3.9/pathlib.py", line 1323, in mkdir
    self._accessor.mkdir(self, mode)
FileNotFoundError: [Errno 2] No such file or directory: '/home/millenagena/Documentos/airflowalura'

During handling of the above exception, another exception occurred:

Traceback (most recent call last):
  File "/usr/lib/python3.9/pathlib.py", line 1323, in mkdir
    self._accessor.mkdir(self, mode)
FileNotFoundError: [Errno 2] No such file or directory: '/home/millenagena/Documentos'

During handling of the above exception, another exception occurred:

Traceback (most recent call last):
  File "/home/kennedy/KR/Programação/00.Estudos/DataEng/Alura/airflow-executores/venv/lib/python3.9/site-packages/airflow/decorators/base.py", line 179, in execute
    return_value = super().execute(context)
  File "/home/kennedy/KR/Programação/00.Estudos/DataEng/Alura/airflow-executores/venv/lib/python3.9/site-packages/airflow/operators/python.py", line 171, in execute
    return_value = self.execute_callable()
  File "/home/kennedy/KR/Programação/00.Estudos/DataEng/Alura/airflow-executores/venv/lib/python3.9/site-packages/airflow/operators/python.py", line 189, in execute_callable
    return self.python_callable(*self.op_args, **self.op_kwargs)
  File "/home/kennedy/KR/Programação/00.Estudos/DataEng/Alura/airflow-executores/airflow/dags/getdag.py", line 17, in get_history
    Path(file_path).parent.mkdir(parents=True, exist_ok=True)
  File "/usr/lib/python3.9/pathlib.py", line 1327, in mkdir
    self.parent.mkdir(parents=True, exist_ok=True)
  File "/usr/lib/python3.9/pathlib.py", line 1327, in mkdir
    self.parent.mkdir(parents=True, exist_ok=True)
  File "/usr/lib/python3.9/pathlib.py", line 1327, in mkdir
    self.parent.mkdir(parents=True, exist_ok=True)
  [Previous line repeated 1 more time]
  File "/usr/lib/python3.9/pathlib.py", line 1323, in mkdir
    self._accessor.mkdir(self, mode)
PermissionError: [Errno 13] Permission denied: '/home/millenagena'
[2024-10-08 16:51:05,576] {taskinstance.py:1395} INFO - Marking task as FAILED. dag_id=get_stocks_dag, task_id=AAPL, execution_date=20220101T000000, start_date=20241008T195104, end_date=20241008T195105
[2024-10-08 16:51:05,721] {standard_task_runner.py:92} ERROR - Failed to execute job 15 for task AAPL ([Errno 13] Permission denied: '/home/millenagena'; 20064)
[2024-10-08 16:51:05,766] {local_task_job.py:156} INFO - Task exited with return code 1
[2024-10-08 16:51:05,823] {local_task_job.py:273} INFO - 0 downstream tasks scheduled from follow-on schedule check
