[2024-10-08 16:51:55,246] {taskinstance.py:1159} INFO - Dependencies all met for <TaskInstance: get_stocks_dag.GOOG scheduled__2022-01-04T00:00:00+00:00 [queued]>
[2024-10-08 16:51:55,253] {taskinstance.py:1159} INFO - Dependencies all met for <TaskInstance: get_stocks_dag.GOOG scheduled__2022-01-04T00:00:00+00:00 [queued]>
[2024-10-08 16:51:55,253] {taskinstance.py:1356} INFO - 
--------------------------------------------------------------------------------
[2024-10-08 16:51:55,253] {taskinstance.py:1357} INFO - Starting attempt 1 of 1
[2024-10-08 16:51:55,253] {taskinstance.py:1358} INFO - 
--------------------------------------------------------------------------------
[2024-10-08 16:51:55,490] {taskinstance.py:1377} INFO - Executing <Task(_PythonDecoratedOperator): GOOG> on 2022-01-04 00:00:00+00:00
[2024-10-08 16:51:55,495] {standard_task_runner.py:52} INFO - Started process 20676 to run task
[2024-10-08 16:51:55,499] {standard_task_runner.py:79} INFO - Running: ['airflow', 'tasks', 'run', 'get_stocks_dag', 'GOOG', 'scheduled__2022-01-04T00:00:00+00:00', '--job-id', '21', '--raw', '--subdir', 'DAGS_FOLDER/getdag.py', '--cfg-path', '/tmp/tmp6s6kezam', '--error-file', '/tmp/tmp2xe153th']
[2024-10-08 16:51:55,500] {standard_task_runner.py:80} INFO - Job 21: Subtask GOOG
[2024-10-08 16:51:55,808] {task_command.py:370} INFO - Running <TaskInstance: get_stocks_dag.GOOG scheduled__2022-01-04T00:00:00+00:00 [running]> on host ken
[2024-10-08 16:51:56,292] {taskinstance.py:1569} INFO - Exporting the following env vars:
AIRFLOW_CTX_DAG_OWNER=airflow
AIRFLOW_CTX_DAG_ID=get_stocks_dag
AIRFLOW_CTX_TASK_ID=GOOG
AIRFLOW_CTX_EXECUTION_DATE=2022-01-04T00:00:00+00:00
AIRFLOW_CTX_TRY_NUMBER=1
AIRFLOW_CTX_DAG_RUN_ID=scheduled__2022-01-04T00:00:00+00:00
[2024-10-08 16:51:56,293] {taskinstance.py:1889} ERROR - Task failed with exception
Traceback (most recent call last):
  File "/usr/lib/python3.9/pathlib.py", line 1323, in mkdir
    self._accessor.mkdir(self, mode)
FileNotFoundError: [Errno 2] No such file or directory: '/home/millenagena/Documentos/airflowalura/stocks/GOOG'

During handling of the above exception, another exception occurred:

Traceback (most recent call last):
  File "/usr/lib/python3.9/pathlib.py", line 1323, in mkdir
    self._accessor.mkdir(self, mode)
FileNotFoundError: [Errno 2] No such file or directory: '/home/millenagena/Documentos/airflowalura/stocks'

During handling of the above exception, another exception occurred:

Traceback (most recent call last):
  File "/usr/lib/python3.9/pathlib.py", line 1323, in mkdir
    self._accessor.mkdir(self, mode)
FileNotFoundError: [Errno 2] No such file or directory: '/home/millenagena/Documentos/airflowalura'

During handling of the above exception, another exception occurred:

Traceback (most recent call last):
  File "/usr/lib/python3.9/pathlib.py", line 1323, in mkdir
    self._accessor.mkdir(self, mode)
FileNotFoundError: [Errno 2] No such file or directory: '/home/millenagena/Documentos'

During handling of the above exception, another exception occurred:

Traceback (most recent call last):
  File "/home/kennedy/KR/Programação/00.Estudos/DataEng/Alura/airflow-executores/venv/lib/python3.9/site-packages/airflow/decorators/base.py", line 179, in execute
    return_value = super().execute(context)
  File "/home/kennedy/KR/Programação/00.Estudos/DataEng/Alura/airflow-executores/venv/lib/python3.9/site-packages/airflow/operators/python.py", line 171, in execute
    return_value = self.execute_callable()
  File "/home/kennedy/KR/Programação/00.Estudos/DataEng/Alura/airflow-executores/venv/lib/python3.9/site-packages/airflow/operators/python.py", line 189, in execute_callable
    return self.python_callable(*self.op_args, **self.op_kwargs)
  File "/home/kennedy/KR/Programação/00.Estudos/DataEng/Alura/airflow-executores/airflow/dags/getdag.py", line 17, in get_history
    Path(file_path).parent.mkdir(parents=True, exist_ok=True)
  File "/usr/lib/python3.9/pathlib.py", line 1327, in mkdir
    self.parent.mkdir(parents=True, exist_ok=True)
  File "/usr/lib/python3.9/pathlib.py", line 1327, in mkdir
    self.parent.mkdir(parents=True, exist_ok=True)
  File "/usr/lib/python3.9/pathlib.py", line 1327, in mkdir
    self.parent.mkdir(parents=True, exist_ok=True)
  [Previous line repeated 1 more time]
  File "/usr/lib/python3.9/pathlib.py", line 1323, in mkdir
    self._accessor.mkdir(self, mode)
PermissionError: [Errno 13] Permission denied: '/home/millenagena'
[2024-10-08 16:51:56,302] {taskinstance.py:1395} INFO - Marking task as FAILED. dag_id=get_stocks_dag, task_id=GOOG, execution_date=20220104T000000, start_date=20241008T195155, end_date=20241008T195156
[2024-10-08 16:51:56,804] {standard_task_runner.py:92} ERROR - Failed to execute job 21 for task GOOG ([Errno 13] Permission denied: '/home/millenagena'; 20676)
[2024-10-08 16:51:56,835] {local_task_job.py:156} INFO - Task exited with return code 1
[2024-10-08 16:51:57,300] {local_task_job.py:273} INFO - 0 downstream tasks scheduled from follow-on schedule check
