[2024-10-08 16:51:08,723] {taskinstance.py:1159} INFO - Dependencies all met for <TaskInstance: get_stocks_dag.MSFT scheduled__2022-01-01T00:00:00+00:00 [queued]>
[2024-10-08 16:51:08,728] {taskinstance.py:1159} INFO - Dependencies all met for <TaskInstance: get_stocks_dag.MSFT scheduled__2022-01-01T00:00:00+00:00 [queued]>
[2024-10-08 16:51:08,728] {taskinstance.py:1356} INFO - 
--------------------------------------------------------------------------------
[2024-10-08 16:51:08,728] {taskinstance.py:1357} INFO - Starting attempt 1 of 1
[2024-10-08 16:51:08,728] {taskinstance.py:1358} INFO - 
--------------------------------------------------------------------------------
[2024-10-08 16:51:08,867] {taskinstance.py:1377} INFO - Executing <Task(_PythonDecoratedOperator): MSFT> on 2022-01-01 00:00:00+00:00
[2024-10-08 16:51:08,880] {standard_task_runner.py:52} INFO - Started process 20095 to run task
[2024-10-08 16:51:08,890] {standard_task_runner.py:79} INFO - Running: ['airflow', 'tasks', 'run', 'get_stocks_dag', 'MSFT', 'scheduled__2022-01-01T00:00:00+00:00', '--job-id', '16', '--raw', '--subdir', 'DAGS_FOLDER/getdag.py', '--cfg-path', '/tmp/tmpkzghvpj0', '--error-file', '/tmp/tmpiumtpp5v']
[2024-10-08 16:51:08,892] {standard_task_runner.py:80} INFO - Job 16: Subtask MSFT
[2024-10-08 16:51:09,092] {task_command.py:370} INFO - Running <TaskInstance: get_stocks_dag.MSFT scheduled__2022-01-01T00:00:00+00:00 [running]> on host ken
[2024-10-08 16:51:09,448] {taskinstance.py:1569} INFO - Exporting the following env vars:
AIRFLOW_CTX_DAG_OWNER=airflow
AIRFLOW_CTX_DAG_ID=get_stocks_dag
AIRFLOW_CTX_TASK_ID=MSFT
AIRFLOW_CTX_EXECUTION_DATE=2022-01-01T00:00:00+00:00
AIRFLOW_CTX_TRY_NUMBER=1
AIRFLOW_CTX_DAG_RUN_ID=scheduled__2022-01-01T00:00:00+00:00
[2024-10-08 16:51:09,453] {taskinstance.py:1889} ERROR - Task failed with exception
Traceback (most recent call last):
  File "/usr/lib/python3.9/pathlib.py", line 1323, in mkdir
    self._accessor.mkdir(self, mode)
FileNotFoundError: [Errno 2] No such file or directory: '/home/millenagena/Documentos/airflowalura/stocks/MSFT'

During handling of the above exception, another exception occurred:

Traceback (most recent call last):
  File "/usr/lib/python3.9/pathlib.py", line 1323, in mkdir
    self._accessor.mkdir(self, mode)
FileNotFoundError: [Errno 2] No such file or directory: '/home/millenagena/Documentos/airflowalura/stocks'

During handling of the above exception, another exception occurred:

Traceback (most recent call last):
  File "/usr/lib/python3.9/pathlib.py", line 1323, in mkdir
    self._accessor.mkdir(self, mode)
FileNotFoundError: [Errno 2] No such file or directory: '/home/millenagena/Documentos/airflowalura'

During handling of the above exception, another exception occurred:

Traceback (most recent call last):
  File "/usr/lib/python3.9/pathlib.py", line 1323, in mkdir
    self._accessor.mkdir(self, mode)
FileNotFoundError: [Errno 2] No such file or directory: '/home/millenagena/Documentos'

During handling of the above exception, another exception occurred:

Traceback (most recent call last):
  File "/home/kennedy/KR/Programação/00.Estudos/DataEng/Alura/airflow-executores/venv/lib/python3.9/site-packages/airflow/decorators/base.py", line 179, in execute
    return_value = super().execute(context)
  File "/home/kennedy/KR/Programação/00.Estudos/DataEng/Alura/airflow-executores/venv/lib/python3.9/site-packages/airflow/operators/python.py", line 171, in execute
    return_value = self.execute_callable()
  File "/home/kennedy/KR/Programação/00.Estudos/DataEng/Alura/airflow-executores/venv/lib/python3.9/site-packages/airflow/operators/python.py", line 189, in execute_callable
    return self.python_callable(*self.op_args, **self.op_kwargs)
  File "/home/kennedy/KR/Programação/00.Estudos/DataEng/Alura/airflow-executores/airflow/dags/getdag.py", line 17, in get_history
    Path(file_path).parent.mkdir(parents=True, exist_ok=True)
  File "/usr/lib/python3.9/pathlib.py", line 1327, in mkdir
    self.parent.mkdir(parents=True, exist_ok=True)
  File "/usr/lib/python3.9/pathlib.py", line 1327, in mkdir
    self.parent.mkdir(parents=True, exist_ok=True)
  File "/usr/lib/python3.9/pathlib.py", line 1327, in mkdir
    self.parent.mkdir(parents=True, exist_ok=True)
  [Previous line repeated 1 more time]
  File "/usr/lib/python3.9/pathlib.py", line 1323, in mkdir
    self._accessor.mkdir(self, mode)
PermissionError: [Errno 13] Permission denied: '/home/millenagena'
[2024-10-08 16:51:09,470] {taskinstance.py:1395} INFO - Marking task as FAILED. dag_id=get_stocks_dag, task_id=MSFT, execution_date=20220101T000000, start_date=20241008T195108, end_date=20241008T195109
[2024-10-08 16:51:09,764] {standard_task_runner.py:92} ERROR - Failed to execute job 16 for task MSFT ([Errno 13] Permission denied: '/home/millenagena'; 20095)
[2024-10-08 16:51:09,785] {local_task_job.py:156} INFO - Task exited with return code 1
[2024-10-08 16:51:09,836] {local_task_job.py:273} INFO - 0 downstream tasks scheduled from follow-on schedule check
